Workbook

Sheet set 1
A1: peptide | B1: n_assays
A2: NLVPMVATV | B2: 576
A3: GILGFVFTL | B3: 274
A4: GLCTLVAML | B4: 219
A5: LLFGYPVYV | B5: 190
A6: SLLMWITQC | B6: 190
A7: YLQPRTFLL | B7: 152
A8: ILAKFLHWL | B8: 129
A9: CLGGLLTMV | B9: 105
A10: CINGVCWTV | B10: 93
A11: ITDQVPFSV | B11: 87
A12: HLVEALYLV | B12: 80
A13: RMFPNAPYL | B13: 69
... A2856: YVYSRVKNL | B2856: 1

Sheet binding peptides
A1: peptide | B1: IC50_nM | C1: log10_IC50 | D1: n_assays
A2: ILKEPVHGV | B2: 566.56618 | C2: 2.7532506 | D2: 16
A3: WLSLLVPFV | B3: 8.7814525 | C3: 0.94356635 | D3: 15
A4: GILGFVFTL | B4: 66.820337 | C4: 1.8249087 | D4: 13
A5: GLSRYVARL | B5: 91.766943 | C5: 1.9626863 | D5: 12
A6: YLVAYQATV | B6: 19.899578 | C6: 1.2988439 | D6: 10
A7: FLLSLGIHL | B7: 11.789723 | C7: 1.0715036 | D7: 9
A8: DLMGYIPLV | B8: 133.72129 | C8: 2.1262006 | D8: 8
A9: SLYNTVATL | B9: 422.90536 | C9: 2.6262432 | D9: 8
A10: ILAGYGAGV | B10: 128.8608 | C10: 2.1101208 | D10: 7
A11: KLTPLCVTL | B11: 62.512931 | C11: 1.7959699 | D11: 7
A12: LLMGTLGIV | B12: 120.3652 | C12: 2.0805009 | D12: 7
A13: NLSWLSLDV | B13: 737.80252 | C13: 2.8679401 | D13: 7
... A1212: RLDKVEAEV | B1212: 36.149689 | C1212: 1.5581046 | D1212: 2
A1213: RLDSYVRSL + PHOS(S4) | B1213: 1 | D1213: 2
A1214: RLFDFNKQA | B1214: 66.609309 | C1214: 1.8235349 | D1214: 2
A1215: RLFSYNFTT | B1215: 0.22748626 | C1215: -0.64304482 | D1215: 2
A1216: RLFTRCAVI | B1216: 209 | C1216: 2.3201463 | D1216: 2
A1217: RLGAVILFV | B1217: 27.276363 | C1217: 1.4357865 | D1217: 2
A1218: RLIDFLKDV | B1218: 37.309516 | C1218: 1.5718196 | D1218: 2
A1219: RLIQNSLTI | B1219: 182.01099 | C1219: 2.2600976 | D1219: 2
A1220: RLITANPVV | B1220: 20 | C1220: 1.30103 | D1220: 2
A1221: RLLDDLVIV | B1221: 0.64849827 | C1221: -0.18809118 | D1221: 2
A1222: RLLGSLNST | B1222: 166.84993 | C1222: 2.222326 | D1222: 2
A1223: RLLPLLALL | B1223: 358.08309 | C1223: 2.5539838 | D1223: 2
A1224: RLMELPVKT | B1224: 118 | C1224: 2.071882 | D1224: 2
A1225: RLMKQDFSV | B1225: 45.898257 | C1225: 1.6617962 | D1225: 2
... A1244: RQASLSISV | B1244: 284.5 | C1244: 2.4540823 | D1244: 2
A1245: RQASLSISV + PHOS(S4) | B1245: 1 | D1245: 2
A1246: RQIFIHYSV | B1246: 0.64949981 | C1246: -0.18742097 | D1246: 2
A1247: RQLLFVVEV | B1247: 1.1148991 | C1247: 0.047235564 | D1247: 2
A1248: RQVSVKLLI | B1248: 250 | C1248: 2.39794 | D1248: 2
A1249: RTLDTAIFT | B1249: 3430.9999 | C1249: 3.5354207 | D1249: 2
A1250: RTLLPILLL | B1250: 307 | C1250: 2.4871384 | D1250: 2
A1251: RTMPNESRV | B1251: 1507.9987 | C1251: 3.178401 | D1251: 2
A1252: RTNDLTALL | B1252: 357 | C1252: 2.5526682 | D1252: 2
A1253: RTNEEFDPV | B1253: 140 | C1253: 2.146128 | D1253: 2
A1254: RTSQKGTVA | B1254: 765 | C1254: 2.8836614 | D1254: 2
A1255: RTVIHLEWL | B1255: 513.49976 | C1255: 2.7105402 | D1255: 2
A1256: RTWKVLSIM | B1256: 840 | C1256: 2.9242793 | D1256: 2
...

Sheet set 2
A1: peptide | B1: in_set1 | C1: in_binding | D1: evidence | E1: IC50_nM | F1: has_IC50 | G1: skippedbyiedb? | H1: n_binding_assays | I1: n_tcell_assays
A2: AAAATCALV | B2: no | C2: yes | D2: binding+ | E2: 1.6127839 | F2: yes | G2: =IF(COUNTIF(#REF!,A2)=0,"missing","ok") -> #REF! | H2: =_xlfn.XLOOKUP(A2,'binding peptides'!A:A,'binding peptides'!D:D,"") -> 3 | I2: =_xlfn.XLOOKUP(A2,'set 1'!A:A,'set 1'!B:B,"")
A3: AAAFVNQHL | B3: no | C3: yes | D3: binding+ | E3: 3.7004441 | F3: yes | G3: =IF(COUNTIF(#REF!,A3)=0,"missing","ok") -> #REF! | H3: =_xlfn.XLOOKUP(A3,'binding peptides'!A:A,'binding peptides'!D:D,"") -> 1 | I3: =_xlfn.XLOOKUP(A3,'set 1'!A:A,'set 1'!B:B,"")
A4: AAAKAAAAV | B4: no | C4: yes | D4: binding+ | E4: 2.5935911 | F4: yes | G4: =IF(COUNTIF(#REF!,A4)=0,"missing","ok") -> #REF! | H4: =_xlfn.XLOOKUP(A4,'binding peptides'!A:A,'binding peptides'!D:D,"") -> 2 | I4: =_xlfn.XLOOKUP(A4,'set 1'!A:A,'set 1'!B:B,"")
A5: AAAWYLWEV | B5: no | C5: yes | D5: binding+ | E5: -0.40893539 | F5: yes | G5: =IF(COUNTIF(#REF!,A5)=0,"missing","ok") -> #REF! | H5: =_xlfn.XLOOKUP(A5,'binding peptides'!A:A,'binding peptides'!D:D,"") -> 3 | I5: =_xlfn.XLOOKUP(A5,'set 1'!A:A,'set 1'!B:B,"")
A6: AAGIGILTV | B6: yes | C6: yes | D6: both | E6: 2.7387282 | F6: yes | G6: =IF(COUNTIF(#REF!,A6)=0,"missing","ok") -> #REF! | H6: =_xlfn.XLOOKUP(A6,'binding peptides'!A:A,'binding peptides'!D:D,"") -> 5 | I6: =_xlfn.XLOOKUP(A6,'set 1'!A:A,'set 1'!B:B,"") -> 60 | M6: Row Labels | N6: Count of evidence
A7: AAIDRQVSV | B7: no | C7: yes | D7: binding+ | E7: 3.167465 | F7: yes | G7: =IF(COUNTIF(#REF!,A7)=0,"missing","ok") -> #REF! | H7: =_xlfn.XLOOKUP(A7,'binding peptides'!A:A,'binding peptides'!D:D,"") -> 2 | I7: =_xlfn.XLOOKUP(A7,'set 1'!A:A,'set 1'!B:B,"") | M7: binding+ | N7: 3022
A8: AALGGSVNI | B8: no | C8: yes | D8: binding+ | E8: 3.1622647 | F8: yes | G8: =IF(COUNTIF(#REF!,A8)=0,"missing","ok") -> #REF! | H8: =_xlfn.XLOOKUP(A8,'binding peptides'!A:A,'binding peptides'!D:D,"") -> 2 | I8: =_xlfn.XLOOKUP(A8,'set 1'!A:A,'set 1'!B:B,"") | M8: both | N8: 480
A9: AALGLWLSV | B9: no | C9: yes | D9: binding+ | E9: 3.4771213 | F9: yes | G9: =IF(COUNTIF(#REF!,A9)=0,"missing","ok") -> #REF! | H9: =_xlfn.XLOOKUP(A9,'binding peptides'!A:A,'binding peptides'!D:D,"") -> 1 | I9: =_xlfn.XLOOKUP(A9,'set 1'!A:A,'set 1'!B:B,"") | M9: T-cell+ | N9: 2375
A10: AAMYQYIFL | B10: no | C10: yes | D10: binding+ | E10: 2.8363241 | F10: yes | G10: =IF(COUNTIF(#REF!,A10)=0,"missing","ok") -> #REF! | H10: =_xlfn.XLOOKUP(A10,'binding peptides'!A:A,'binding peptides'!D:D,"") -> 2 | I10: =_xlfn.XLOOKUP(A10,'set 1'!A:A,'set 1'!B:B,"") | M10: Grand Total | N10: 5877
A11: AASPMLYQL | B11: no | C11: yes | D11: binding+ | E11: 2.9638185 | F11: yes | G11: =IF(COUNTIF(#REF!,A11)=0,"missing","ok") -> #REF! | H11: =_xlfn.XLOOKUP(A11,'binding peptides'!A:A,'binding peptides'!D:D,"") -> 3 | I11: =_xlfn.XLOOKUP(A11,'set 1'!A:A,'set 1'!B:B,"")
A12: AASSTHRKV | B12: no | C12: yes | D12: binding+ | E12: 3.4220148 | F12: yes | G12: =IF(COUNTIF(#REF!,A12)=0,"missing","ok") -> #REF! | H12: =_xlfn.XLOOKUP(A12,'binding peptides'!A:A,'binding peptides'!D:D,"") -> 2 | I12: =_xlfn.XLOOKUP(A12,'set 1'!A:A,'set 1'!B:B,"")
A13: AAVSHLTTL | B13: no | C13: yes | D13: binding+ | E13: 3.0222221 | F13: yes | G13: =IF(COUNTIF(#REF!,A13)=0,"missing","ok") -> #REF! | H13: =_xlfn.XLOOKUP(A13,'binding peptides'!A:A,'binding peptides'!D:D,"") -> 1 | I13: =_xlfn.XLOOKUP(A13,'set 1'!A:A,'set 1'!B:B,"")
A14: AIAKAAAAV | B14: no | C14: yes | D14: binding+ | E14: 2.3619732 | F14: yes | G14: =IF(COUNTIF(#REF!,A14)=0,"missing","ok") -> #REF! | H14: =_xlfn.XLOOKUP(A14,'binding peptides'!A:A,'binding peptides'!D:D,"") -> 2 | I14: =_xlfn.XLOOKUP(A14,'set 1'!A:A,'set 1'!B:B,"")
A15: AIALGVATA | B15: no | C15: yes | D15: binding+ | E15: 2.9350032 | F15: yes | G15: =IF(COUNTIF(#REF!,A15)=0,"missing","ok") -> #REF! | H15: =_xlfn.XLOOKUP(A15,'binding peptides'!A:A,'binding peptides'!D:D,"") -> 1 | I15: =_xlfn.XLOOKUP(A15,'set 1'!A:A,'set 1'!B:B,"")
A16: AIFNNRNLA | B16: no | C16: yes | D16: binding+ | E16: 3.5014015 | F16: yes | G16: =IF(COUNTIF(#REF!,A16)=0,"missing","ok") -> #REF! | H16: =_xlfn.XLOOKUP(A16,'binding peptides'!A:A,'binding peptides'!D:D,"") -> 2 | I16: =_xlfn.XLOOKUP(A16,'set 1'!A:A,'set 1'!B:B,"")
A17: AIFTDASTV | B17: no | C17: yes | D17: binding+ | E17: 2.842921 | F17: yes | G17: =IF(COUNTIF(#REF!,A17)=0,"missing","ok") -> #REF! | H17: =_xlfn.XLOOKUP(A17,'binding peptides'!A:A,'binding peptides'!D:D,"") -> 2 | I17: =_xlfn.XLOOKUP(A17,'set 1'!A:A,'set 1'!B:B,"")
A18: AIHNVVHAI | B18: no | C18: yes | D18: binding+ | E18: 2.2201081 | F18: yes | G18: =IF(COUNTIF(#REF!,A18)=0,"missing","ok") -> #REF! | H18: =_xlfn.XLOOKUP(A18,'binding peptides'!A:A,'binding peptides'!D:D,"") -> 1 | I18: =_xlfn.XLOOKUP(A18,'set 1'!A:A,'set 1'!B:B,"")
A19: AIIDIEPDL | B19: no | C19: yes | D19: binding+ | E19: 2.4778439 | F19: yes | G19: =IF(COUNTIF(#REF!,A19)=0,"missing","ok") -> #REF! | H19: =_xlfn.XLOOKUP(A19,'binding peptides'!A:A,'binding peptides'!D:D,"") -> 2 | I19: =_xlfn.XLOOKUP(A19,'set 1'!A:A,'set 1'!B:B,"")
A20: AIIDPLIYA | B20: yes | C20: yes | D20: both | E20: 2.4165627 | F20: yes | G20: =IF(COUNTIF(#REF!,A20)=0,"missing","ok") -> #REF! | H20: =_xlfn.XLOOKUP(A20,'binding peptides'!A:A,'binding peptides'!D:D,"") -> 2 | I20: =_xlfn.XLOOKUP(A20,'set 1'!A:A,'set 1'!B:B,"") -> 1
A21: AIIGLCAYA | B21: no | C21: yes | D21: binding+ | E21: 1.9092878 | F21: yes | G21: =IF(COUNTIF(#REF!,A21)=0,"missing","ok") -> #REF! | H21: =_xlfn.XLOOKUP(A21,'binding peptides'!A:A,'binding peptides'!D:D,"") -> 2 | I21: =_xlfn.XLOOKUP(A21,'set 1'!A:A,'set 1'!B:B,"")
A22: AIILASFSA | B22: yes | C22: yes | D22: both | E22: 2.4377506 | F22: yes | G22: =IF(COUNTIF(#REF!,A22)=0,"missing","ok") -> #REF! | H22: =_xlfn.XLOOKUP(A22,'binding peptides'!A:A,'binding peptides'!D:D,"") -> 2 | I22: =_xlfn.XLOOKUP(A22,'set 1'!A:A,'set 1'!B:B,"") -> 1
... A3503: YVYKIVSQL | B3503: no | C3503: yes | D3503: binding+ | E3503: 2.4927604 | F3503: yes | G3503: =IF(COUNTIF(#REF!,A3503)=0,"missing","ok") -> #REF! | H3503: =_xlfn.XLOOKUP(A3503,'binding peptides'!A:A,'binding peptides'!D:D,"") -> 1 | I3503: =_xlfn.XLOOKUP(A3503,'set 1'!A:A,'set 1'!B:B,"")
A3504: AAAGFLFCV | B3504: yes | C3504: no | D3504: T-cell+ | F3504: no | G3504: =IF(COUNTIF(#REF!,A3504)=0,"missing","ok") -> #REF! | H3504: =_xlfn.XLOOKUP(A3504,'binding peptides'!A:A,'binding peptides'!D:D,"") | I3504: =_xlfn.XLOOKUP(A3504,'set 1'!A:A,'set 1'!B:B,"") -> 1
A3505: AAERKHRHL | B3505: yes | C3505: no | D3505: T-cell+ | F3505: no | G3505: =IF(COUNTIF(#REF!,A3505)=0,"missing","ok") -> #REF! | H3505: =_xlfn.XLOOKUP(A3505,'binding peptides'!A:A,'binding peptides'!D:D,"") | I3505: =_xlfn.XLOOKUP(A3505,'set 1'!A:A,'set 1'!B:B,"") -> 1
A3506: AALFFFDID | B3506: yes | C3506: no | D3506: T-cell+ | F3506: no | G3506: =IF(COUNTIF(#REF!,A3506)=0,"missing","ok") -> #REF! | H3506: =_xlfn.XLOOKUP(A3506,'binding peptides'!A:A,'binding peptides'!D:D,"") | I3506: =_xlfn.XLOOKUP(A3506,'set 1'!A:A,'set 1'!B:B,"") -> 1
A3507: AALPILFQV | B3507: yes | C3507: no | D3507: T-cell+ | F3507: no | G3507: =IF(COUNTIF(#REF!,A3507)=0,"missing","ok") -> #REF! | H3507: =_xlfn.XLOOKUP(A3507,'binding peptides'!A:A,'binding peptides'!D:D,"") | I3507: =_xlfn.XLOOKUP(A3507,'set 1'!A:A,'set 1'!B:B,"") -> 4
A3508: AAQPKRRRH | B3508: yes | C3508: no | D3508: T-cell+ | F3508: no | G3508: =IF(COUNTIF(#REF!,A3508)=0,"missing","ok") -> #REF! | H3508: =_xlfn.XLOOKUP(A3508,'binding peptides'!A:A,'binding peptides'!D:D,"") | I3508: =_xlfn.XLOOKUP(A3508,'set 1'!A:A,'set 1'!B:B,"") -> 1
A3509: AEISRNDLI | B3509: yes | C3509: no | D3509: T-cell+ | F3509: no | G3509: =IF(COUNTIF(#REF!,A3509)=0,"missing","ok") -> #REF! | H3509: =_xlfn.XLOOKUP(A3509,'binding peptides'!A:A,'binding peptides'!D:D,"") | I3509: =_xlfn.XLOOKUP(A3509,'set 1'!A:A,'set 1'!B:B,"") -> 4
A3510: AEMEFCPCC | B3510: yes | C3510: no | D3510: T-cell+ | F3510: no | G3510: =IF(COUNTIF(#REF!,A3510)=0,"missing","ok") -> #REF! | H3510: =_xlfn.XLOOKUP(A3510,'binding peptides'!A:A,'binding peptides'!D:D,"") | I3510: =_xlfn.XLOOKUP(A3510,'set 1'!A:A,'set 1'!B:B,"") -> 5
A3511: AETLYLAVN | B3511: yes | C3511: no | D3511: T-cell+ | F3511: no | G3511: =IF(COUNTIF(#REF!,A3511)=0,"missing","ok") -> #REF! | H3511: =_xlfn.XLOOKUP(A3511,'binding peptides'!A:A,'binding peptides'!D:D,"") | I3511: =_xlfn.XLOOKUP(A3511,'set 1'!A:A,'set 1'!B:B,"") -> 2
A3512: AFLGERVTL | B3512: yes | C3512: no | D3512: T-cell+ | F3512: no | G3512: =IF(COUNTIF(#REF!,A3512)=0,"missing","ok") -> #REF! | H3512: =_xlfn.XLOOKUP(A3512,'binding peptides'!A:A,'binding peptides'!D:D,"") | I3512: =_xlfn.XLOOKUP(A3512,'set 1'!A:A,'set 1'!B:B,"") -> 3
A3513: AIDAALTFV | B3513: yes | C3513: no | D3513: T-cell+ | F3513: no | G3513: =IF(COUNTIF(#REF!,A3513)=0,"missing","ok") -> #REF! | H3513: =_xlfn.XLOOKUP(A3513,'binding peptides'!A:A,'binding peptides'!D:D,"") | I3513: =_xlfn.XLOOKUP(A3513,'set 1'!A:A,'set 1'!B:B,"") -> 6
A3514: AIFYLITPV | B3514: yes | C3514: no | D3514: T-cell+ | F3514: no | G3514: =IF(COUNTIF(#REF!,A3514)=0,"missing","ok") -> #REF! | H3514: =_xlfn.XLOOKUP(A3514,'binding peptides'!A:A,'binding peptides'!D:D,"") | I3514: =_xlfn.XLOOKUP(A3514,'set 1'!A:A,'set 1'!B:B,"") -> 3
A3515: AIGEVLVSV | B3515: yes | C3515: no | D3515: T-cell+ | F3515: no | G3515: =IF(COUNTIF(#REF!,A3515)=0,"missing","ok") -> #REF! | H3515: =_xlfn.XLOOKUP(A3515,'binding peptides'!A:A,'binding peptides'!D:D,"") | I3515: =_xlfn.XLOOKUP(A3515,'set 1'!A:A,'set 1'!B:B,"") -> 2
... A5878: YYPIIRKQF | B5878: yes | C5878: no | D5878: T-cell+ | F5878: no | G5878: =IF(COUNTIF(#REF!,A5878)=0,"missing","ok") -> #REF! | H5878: =_xlfn.XLOOKUP(A5878,'binding peptides'!A:A,'binding peptides'!D:D,"") | I5878: =_xlfn.XLOOKUP(A5878,'set 1'!A:A,'set 1'!B:B,"") -> 3
